<?xml version="1.0" ?>

<robot name="bcrobot">
  <!-- Link Definitions -->
  
  <!-- base_footprint -->
  <link name="base_footprint">
    <inertial>
      <mass value="1.0"/>
      <origin xyz="0 0 0" rpy="0 0 0"/>
      <inertia ixx="0.1" ixy="0.0" ixz="0.0" iyy="0.1" iyz="0.0" izz="0.1"/>
    </inertial>
  </link>

  <!-- base_link -->
  <link name="base_link">
    <inertial>
      <mass value="5.0"/>
      <origin xyz="0 0 0" rpy="0 0 0"/>
      <inertia ixx="0.2" ixy="0.0" ixz="0.0" iyy="0.2" iyz="0.0" izz="0.2"/>
    </inertial>
    <visual>
      <geometry>
        <box size="0.09 0.18 0.035"/> <!-- 로봇의 기본 몸체 크기 -->
      </geometry>
      <material name="grey">
        <color rgba="0.5 0.5 0.5 1.0"/>
      </material>
    </visual>
    <collision>
      <geometry>
        <box size="0.09 0.18 0.035"/> <!-- 로봇의 기본 몸체 크기 -->
      </geometry>
    </collision>
  </link>

  <!-- Left and Right Wheel Definitions -->
  
  <!-- Left Front Wheel -->
  <link name="left_front_wheel">
    <inertial>
      <mass value="0.5"/>
      <origin xyz="0 0 0" rpy="0 0 0"/>
      <inertia ixx="0.01" ixy="0.0" ixz="0.0" iyy="0.01" iyz="0.0" izz="0.01"/>
    </inertial>
    <visual>
      <origin xyz="0 0 0" rpy="0 1.5708 0"/> <!-- 수평으로 놓이도록 회전 설정 -->
      <geometry>
        <cylinder length="0.042" radius="0.04"/> <!-- 바퀴의 크기 -->
      </geometry>
      <material name="black">
        <color rgba="0.0 0.0 0.0 1.0"/>
      </material>
    </visual>
    <collision>
      <origin xyz="0 0 0" rpy="0 1.5708 0"/> <!-- 수평으로 놓이도록 회전 설정 -->
      <geometry>
        <cylinder length="0.042" radius="0.04"/> <!-- 바퀴의 크기 -->
      </geometry>
    </collision>
  </link>

  <!-- Left Rear Wheel -->
  <link name="left_rear_wheel">
    <inertial>
      <mass value="0.5"/>
      <origin xyz="0 0 0" rpy="0 0 0"/>
      <inertia ixx="0.01" ixy="0.0" ixz="0.0" iyy="0.01" iyz="0.0" izz="0.01"/>
    </inertial>
    <visual>
      <origin xyz="0 0 0" rpy="0 1.5708 0"/> <!-- 수평으로 놓이도록 회전 설정 -->
      <geometry>
        <cylinder length="0.042" radius="0.04"/> <!-- 바퀴의 크기 -->
      </geometry>
      <material name="black">
        <color rgba="0.0 0.0 0.0 1.0"/>
      </material>
    </visual>
    <collision>
      <origin xyz="0 0 0" rpy="0 1.5708 0"/> <!-- 수평으로 놓이도록 회전 설정 -->
      <geometry>
        <cylinder length="0.042" radius="0.04"/> <!-- 바퀴의 크기 -->
      </geometry>
    </collision>
  </link>

  <!-- Right Front Wheel -->
  <link name="right_front_wheel">
    <inertial>
      <mass value="0.5"/>
      <origin xyz="0 0 0" rpy="0 0 0"/>
      <inertia ixx="0.01" ixy="0.0" ixz="0.0" iyy="0.01" iyz="0.0" izz="0.01"/>
    </inertial>
    <visual>
      <origin xyz="0 0 0" rpy="0 1.5708 0"/> <!-- 수평으로 놓이도록 회전 설정 -->
      <geometry>
        <cylinder length="0.042" radius="0.04"/> <!-- 바퀴의 크기 -->
      </geometry>
      <material name="black">
        <color rgba="0.0 0.0 0.0 1.0"/>
      </material>
    </visual>
    <collision>
      <origin xyz="0 0 0" rpy="0 1.5708 0"/> <!-- 수평으로 놓이도록 회전 설정 -->
      <geometry>
        <cylinder length="0.042" radius="0.04"/> <!-- 바퀴의 크기 -->
      </geometry>
    </collision>
  </link>

  <!-- Right Rear Wheel -->
  <link name="right_rear_wheel">
    <inertial>
      <mass value="0.5"/>
      <origin xyz="0 0 0" rpy="0 0 0"/>
      <inertia ixx="0.01" ixy="0.0" ixz="0.0" iyy="0.01" iyz="0.0" izz="0.01"/>
    </inertial>
    <visual>
      <origin xyz="0 0 0" rpy="0 1.5708 0"/> <!-- 수평으로 놓이도록 회전 설정 -->
      <geometry>
        <cylinder length="0.042" radius="0.04"/> <!-- 바퀴의 크기 -->
      </geometry>
      <material name="black">
        <color rgba="0.0 0.0 0.0 1.0"/>
      </material>
    </visual>
    <collision>
      <origin xyz="0 0 0" rpy="0 1.5708 0"/> <!-- 수평으로 놓이도록 회전 설정 -->
      <geometry>
        <cylinder length="0.042" radius="0.04"/> <!-- 바퀴의 크기 -->
      </geometry>
    </collision>
  </link>

  <!-- Joints Definitions -->
  
  <!-- base_link to base_footprint -->
  <joint name="base_joint" type="fixed">
    <parent link="base_footprint"/>
    <child link="base_link" />
    <origin xyz="0 0 0.06" rpy="0 0 0"/>
  </joint>

  <!-- Left wheels joint -->
  <joint name="left_wheel_joint" type="continuous">
    <parent link="base_link"/>
    <child link="left_front_wheel"/>
    <origin xyz="0.06 0.045 -0.02" rpy="0 0 0"/>
    <axis xyz="0 1 0"/> <!-- 회전축 설정 -->
  </joint>

  <joint name="left_rear_wheel_joint" type="fixed">
    <parent link="left_front_wheel"/>
    <child link="left_rear_wheel"/>
    <origin xyz="0 -0.12 0"/>
  </joint>

  <!-- Right wheels joint -->
  <joint name="right_wheel_joint" type="continuous">
    <parent link="base_link"/>
    <child link="right_front_wheel"/>
    <origin xyz="-0.06 0.045 -0.02" rpy="0 0 0"/>
    <axis xyz="0 1 0"/>
  </joint>

  <joint name="right_rear_wheel_joint" type="fixed">
    <parent link="right_front_wheel"/>
    <child link="right_rear_wheel"/>
    <origin xyz="0 -0.12 0"/>
  </joint>

  <!-- Gazebo-specific Plugins -->
  <gazebo>
    <plugin name="gazebo_ros_control" filename="libgazebo_ros_control.so">
      <robotNamespace>/bcrobot</robotNamespace>
      <legacyModeNS>true</legacyModeNS>
    </plugin>
  </gazebo>
  
  <!-- Gazebo wheel plugins for velocity control -->
  <gazebo>
    <plugin name="gazebo_ros_diff_drive" filename="libgazebo_ros_diff_drive.so">
      <ros>
        <namespace>/bcrobot</namespace>
        <remapping>cmd_vel:=/cmd_vel</remapping>
      </ros>
      <updateRate>100.0</updateRate>
      <leftJoint>left_wheel_joint</leftJoint>
      <rightJoint>right_wheel_joint</rightJoint>
      <wheelSeparation>0.09</wheelSeparation>
      <wheelDiameter>0.08</wheelDiameter>
      <torque>5.0</torque>
    </plugin>
  </gazebo>

</robot>
